<?xml version="1.0" encoding="UTF-8"?>
<!-- Generated by org.testng.reporters.JUnitReportReporter -->
<testsuite skipped="1" hostname="DESKTOP-7IJ20C2" name="demo.demo.F" tests="6" failures="0" timestamp="12 Feb 2018 15:50:25 GMT" time="0.050" errors="1">
  <testcase name="PassTest" time="0.004" classname="demo.demo.F"/>
  <testcase name="SkipTest" time="0.020" classname="demo.demo.F">
    <skipped/>
  </testcase> <!-- SkipTest -->
  <testcase name="FailTest" time="0.010" classname="demo.demo.F">
    <error type="junit.framework.AssertionFailedError">
      <![CDATA[junit.framework.AssertionFailedErrorat junit.framework.Assert.fail(Assert.java:47)at junit.framework.Assert.assertTrue(Assert.java:20)at junit.framework.Assert.assertTrue(Assert.java:27)at demo.demo.E.FailTest(E.java:49)at sun.reflect.NativeMethodAccessorImpl.invoke0(Native Method)at sun.reflect.NativeMethodAccessorImpl.invoke(Unknown Source)at sun.reflect.DelegatingMethodAccessorImpl.invoke(Unknown Source)at java.lang.reflect.Method.invoke(Unknown Source)at org.testng.internal.MethodInvocationHelper.invokeMethod(MethodInvocationHelper.java:124)at org.testng.internal.Invoker.invokeMethod(Invoker.java:571)at org.testng.internal.Invoker.invokeTestMethod(Invoker.java:707)at org.testng.internal.Invoker.invokeTestMethods(Invoker.java:979)at org.testng.internal.TestMethodWorker.invokeTestMethods(TestMethodWorker.java:125)at org.testng.internal.TestMethodWorker.run(TestMethodWorker.java:109)at org.testng.TestRunner.privateRun(TestRunner.java:648)at org.testng.TestRunner.run(TestRunner.java:505)at org.testng.SuiteRunner.runTest(SuiteRunner.java:455)at org.testng.SuiteRunner.runSequentially(SuiteRunner.java:450)at org.testng.SuiteRunner.privateRun(SuiteRunner.java:415)at org.testng.SuiteRunner.run(SuiteRunner.java:364)at org.testng.SuiteRunnerWorker.runSuite(SuiteRunnerWorker.java:52)at org.testng.SuiteRunnerWorker.run(SuiteRunnerWorker.java:84)at org.testng.TestNG.runSuitesSequentially(TestNG.java:1187)at org.testng.TestNG.runSuitesLocally(TestNG.java:1116)at org.testng.TestNG.runSuites(TestNG.java:1028)at org.testng.TestNG.run(TestNG.java:996)at org.testng.remote.AbstractRemoteTestNG.run(AbstractRemoteTestNG.java:114)at org.testng.remote.RemoteTestNG.initAndRun(RemoteTestNG.java:251)at org.testng.remote.RemoteTestNG.main(RemoteTestNG.java:77)]]>
    </error>
  </testcase> <!-- FailTest -->
  <testcase name="Test1" time="0.007" classname="demo.demo.F"/>
  <testcase name="Test2" time="0.004" classname="demo.demo.F"/>
  <testcase name="Test3" time="0.005" classname="demo.demo.F"/>
</testsuite> <!-- demo.demo.F -->
